Workbook

Sheet Summary
A1: Kwazy — Rove Watch data
A2: Exported from backup 2026-08-13 · USD rate 95 · markup uses GST 2.0 slabs, ITC only when purchase AND sale are above 7,500/night
A4: City | B4: Properties | C4: Priced rows | D4: Median markup | E4: Mean markup | F4: Median agent | G4: Below cost
A5: Goa | B5: 41 | C5: =COUNT(Goa!Q:Q) -> 130 | D5: =IFERROR(MEDIAN(Goa!Q:Q),"") -> 0.13656716 | E5: =IFERROR(AVERAGE(Goa!Q:Q),"") -> 0.19442971 | F5: =IFERROR(MEDIAN(Goa!R:R),"") -> 0.12082962 | G5: =COUNTIF(Goa!Q:Q,"<0") -> 5
A6: Lonavala/Mahabaleshwar | B6: 36 | C6: =COUNT('Lonavala-Mahabaleshwar'!Q:Q) -> 92 | D6: =IFERROR(MEDIAN('Lonavala-Mahabaleshwar'!Q:Q),"") -> 0.063281107 | E6: =IFERROR(AVERAGE('Lonavala-Mahabaleshwar'!Q:Q),"") -> 0.057666941 | F6: =IFERROR(MEDIAN('Lonavala-Mahabaleshwar'!R:R),"") -> 0.053628057 | G6: =COUNTIF('Lonavala-Mahabaleshwar'!Q:Q,"<0") -> 24
A7: Mussorie | B7: 27 | C7: =COUNT(Mussorie!Q:Q) -> 88 | D7: =IFERROR(MEDIAN(Mussorie!Q:Q),"") -> 0.14531947 | E7: =IFERROR(AVERAGE(Mussorie!Q:Q),"") -> 0.16514721 | F7: =IFERROR(MEDIAN(Mussorie!R:R),"") -> 0.12624739 | G7: =COUNTIF(Mussorie!Q:Q,"<0") -> 4
A8: ho chi minh | B8: 21 | C8: =COUNT('ho chi minh'!Q:Q) -> 81 | D8: =IFERROR(MEDIAN('ho chi minh'!Q:Q),"") -> 0.11752123 | E8: =IFERROR(AVERAGE('ho chi minh'!Q:Q),"") -> 0.16735606 | F8: =IFERROR(MEDIAN('ho chi minh'!R:R),"") -> 0.099594264 | G8: =COUNTIF('ho chi minh'!Q:Q,"<0") -> 7
A9: Hanoi | B9: 17 | C9: =COUNT(Hanoi!Q:Q) -> 46 | D9: =IFERROR(MEDIAN(Hanoi!Q:Q),"") -> 0.079743685 | E9: =IFERROR(AVERAGE(Hanoi!Q:Q),"") -> 0.10114071 | F9: =IFERROR(MEDIAN(Hanoi!R:R),"") -> 0.067579394 | G9: =COUNTIF(Hanoi!Q:Q,"<0") -> 4
A10: Shimla | B10: 17 | C10: =COUNT(Shimla!Q:Q) -> 59 | D10: =IFERROR(MEDIAN(Shimla!Q:Q),"") -> 0.11057642 | E10: =IFERROR(AVERAGE(Shimla!Q:Q),"") -> 0.13125692 | F10: =IFERROR(MEDIAN(Shimla!R:R),"") -> 0.093708827 | G10: =COUNTIF(Shimla!Q:Q,"<0") -> 12
A11: Jaipur/Udaipur | B11: 16 | C11: =COUNT('Jaipur-Udaipur'!Q:Q) -> 49 | D11: =IFERROR(MEDIAN('Jaipur-Udaipur'!Q:Q),"") -> 0.10157833 | E11: =IFERROR(AVERAGE('Jaipur-Udaipur'!Q:Q),"") -> 0.12064502 | F11: =IFERROR(MEDIAN('Jaipur-Udaipur'!R:R),"") -> 0.089218137 | G11: =COUNTIF('Jaipur-Udaipur'!Q:Q,"<0") -> 0
A12: Manali/Mussoorie | B12: 12 | C12: =COUNT('Manali-Mussoorie'!Q:Q) -> 44 | D12: =IFERROR(MEDIAN('Manali-Mussoorie'!Q:Q),"") -> 0.073537637 | E12: =IFERROR(AVERAGE('Manali-Mussoorie'!Q:Q),"") -> 0.09638221 | F12: =IFERROR(MEDIAN('Manali-Mussoorie'!R:R),"") -> 0.062320032 | G12: =COUNTIF('Manali-Mussoorie'!Q:Q,"<0") -> 3
A13: Dubai | B13: 11 | C13: =COUNT(Dubai!Q:Q) -> 33 | D13: =IFERROR(MEDIAN(Dubai!Q:Q),"") -> 0.15917814 | E13: =IFERROR(AVERAGE(Dubai!Q:Q),"") -> 0.20988984 | F13: =IFERROR(MEDIAN(Dubai!R:R),"") -> 0.13568606 | G13: =COUNTIF(Dubai!Q:Q,"<0") -> 2
A14: Tokyo | B14: 10 | C14: =COUNT(Tokyo!Q:Q) -> 15 | D14: =IFERROR(MEDIAN(Tokyo!Q:Q),"") -> 0.31366722 | E14: =IFERROR(AVERAGE(Tokyo!Q:Q),"") -> 0.36695074 | F14: =IFERROR(MEDIAN(Tokyo!R:R),"") -> 0.26733883 | G14: =COUNTIF(Tokyo!Q:Q,"<0") -> 0
A15: Bengaluru (metro) | B15: 1 | C15: =COUNT('Bengaluru (metro)'!Q:Q) -> 0 | D15: =IFERROR(MEDIAN('Bengaluru (metro)'!Q:Q),"") | E15: =IFERROR(AVERAGE('Bengaluru (metro)'!Q:Q),"") | F15: =IFERROR(MEDIAN('Bengaluru (metro)'!R:R),"") | G15: =COUNTIF('Bengaluru (metro)'!Q:Q,"<0") -> 0
A16: ALL CITIES | B16: =SUM(B5:B15) -> 209 | C16: =SUM(C5:C15) -> 637 | D16: =IFERROR(MEDIAN(Goa!Q:Q,'Jaipur-Udaipur'!Q:Q,'Manali-Mussoorie'!Q:Q,Hanoi!Q:Q,Tokyo!Q:Q,'ho chi minh'!Q:Q,Mussorie!Q:Q,Dubai!Q:Q,'Bengaluru (metro)'!Q:Q,Shimla!Q:Q,'Lonavala-Mahabaleshwar'!Q:Q),"") -> 0.1184071 | E16: =IFERROR(AVERAGE(Goa!Q:Q,'Jaipur-Udaipur'!Q:Q,'Manali-Mussoorie'!Q:Q,Hanoi!Q:Q,Tokyo!Q:Q,'ho chi minh'!Q:Q,Mussorie!Q:Q,Dubai!Q:Q,'Bengaluru (metro)'!Q:Q,Shimla!Q:Q,'Lonavala-Mahabaleshwar'!Q:Q),"") -> 0.14701679 | G16: =SUM(G5:G15) -> 61

Sheet Goa
A1: City | B1: Property | C1: Season slot | D1: Check-in | E1: Check-out | F1: Nights | G1: TBO (stay) | H1: MMT (stay) | I1: Goibibo (stay) | J1: Booking (stay) | K1: Agoda (stay) | L1: Rove ($) | M1: Return % | N1: TBO / night | O1: Cheapest OTA / night | P1: Rove / night (INR) | Q1: Markup % | R1: Agent % | S1: Rove mk % | T1: Flag
A2: Goa | B2: Beleza By The Beach | C2: ~7d · mid-Jul | D2: 2026-08-13 | E2: 2026-08-16 | F2: =IF(OR(D2="",E2=""),1,MAX(1,DATEVALUE(E2)-DATEVALUE(D2))) -> 3 | G2: 19505 | H2: 24934 | L2: 372.02 | M2: 0.28 | N2: =IF(G2="","",G2/F2) -> 6501.6667 | O2: =IF(COUNT(H2:K2)=0,"",MIN(H2:K2)/F2) -> 8311.3333 | P2: =IF(L2="","",L2*95/F2) -> 11780.633 | Q2: =IF(OR(N2="",O2=""),"",(IF(AND(N2>7500,O2>7500),O2/(1+IF(O2<=1000,0,IF(O2<=7500,0.05,0.18)))-IF(AND(N2>7500,O2>7500),N2/1.18,N2),(O2-IF(AND(N2>7500,O2>7500),N2/1.18,N2))/(1+IF(O2<=1000,0,IF(O2<=7500,0.05,0.18)))))/(IF(AND(N2>7500,O2>7500),N2/1.18,N2))) -> 0.23588041 | R2: =IF(OR(N2="",O2=""),"",((O2-N2)/1.18)/N2) -> 0.23588041 | S2: =IF(OR(P2="",O2=""),"",(P2-O2)/O2) -> 0.41741798 | T2: =IF(AND(D2="",G2<>""),"no dates - assumed 1 night",IF(Q2="","",IF(Q2>1.5,"check: markup >150%",IF(Q2<0,"below cost",""))))
A3: Goa | B3: Beleza By The Beach | C3: ~30d · mid-Aug | D3: 2026-08-28 | E3: 2026-08-31 | F3: =IF(OR(D3="",E3=""),1,MAX(1,DATEVALUE(E3)-DATEVALUE(D3))) -> 3 | G3: 29009 | H3: 30319 | L3: 317.82 | M3: 0.12 | N3: =IF(G3="","",G3/F3) -> 9669.6667 | O3: =IF(COUNT(H3:K3)=0,"",MIN(H3:K3)/F3) -> 10106.333 | P3: =IF(L3="","",L3*95/F3) -> 10064.3 | Q3: =IF(OR(N3="",O3=""),"",(IF(AND(N3>7500,O3>7500),O3/(1+IF(O3<=1000,0,IF(O3<=7500,0.05,0.18)))-IF(AND(N3>7500,O3>7500),N3/1.18,N3),(O3-IF(AND(N3>7500,O3>7500),N3/1.18,N3))/(1+IF(O3<=1000,0,IF(O3<=7500,0.05,0.18)))))/(IF(AND(N3>7500,O3>7500),N3/1.18,N3))) -> 0.045158399 | R3: =IF(OR(N3="",O3=""),"",((O3-N3)/1.18)/N3) -> 0.03826983 | S3: =IF(OR(P3="",O3=""),"",(P3-O3)/O3) -> -0.0041591082 | T3: =IF(AND(D3="",G3<>""),"no dates - assumed 1 night",IF(Q3="","",IF(Q3>1.5,"check: markup >150%",IF(Q3<0,"below cost",""))))
A4: Goa | B4: Beleza By The Beach | C4: mid-Oct · Diwali | D4: 2026-11-12 | E4: 2026-11-15 | F4: =IF(OR(D4="",E4=""),1,MAX(1,DATEVALUE(E4)-DATEVALUE(D4))) -> 3 | G4: 68689 | H4: 71904 | L4: 753.75 | M4: 0.12 | N4: =IF(G4="","",G4/F4) -> 22896.333 | O4: =IF(COUNT(H4:K4)=0,"",MIN(H4:K4)/F4) -> 23968 | P4: =IF(L4="","",L4*95/F4) -> 23868.75 | Q4: =IF(OR(N4="",O4=""),"",(IF(AND(N4>7500,O4>7500),O4/(1+IF(O4<=1000,0,IF(O4<=7500,0.05,0.18)))-IF(AND(N4>7500,O4>7500),N4/1.18,N4),(O4-IF(AND(N4>7500,O4>7500),N4/1.18,N4))/(1+IF(O4<=1000,0,IF(O4<=7500,0.05,0.18)))))/(IF(AND(N4>7500,O4>7500),N4/1.18,N4))) -> 0.046805165 | R4: =IF(OR(N4="",O4=""),"",((O4-N4)/1.18)/N4) -> 0.039665394 | S4: =IF(OR(P4="",O4=""),"",(P4-O4)/O4) -> -0.0041409379 | T4: =IF(AND(D4="",G4<>""),"no dates - assumed 1 night",IF(Q4="","",IF(Q4>1.5,"check: markup >150%",IF(Q4<0,"below cost",""))))
A5: Goa | B5: Beleza By The Beach | C5: 27–30 Dec | D5: 2026-12-29 | E5: 2027-01-01 | F5: =IF(OR(D5="",E5=""),1,MAX(1,DATEVALUE(E5)-DATEVALUE(D5))) -> 3 | G5: 56367 | H5: 98454 | L5: 1032.09 | M5: 0.12 | N5: =IF(G5="","",G5/F5) -> 18789 | O5: =IF(COUNT(H5:K5)=0,"",MIN(H5:K5)/F5) -> 32818 | P5: =IF(L5="","",L5*95/F5) -> 32682.85 | Q5: =IF(OR(N5="",O5=""),"",(IF(AND(N5>7500,O5>7500),O5/(1+IF(O5<=1000,0,IF(O5<=7500,0.05,0.18)))-IF(AND(N5>7500,O5>7500),N5/1.18,N5),(O5-IF(AND(N5>7500,O5>7500),N5/1.18,N5))/(1+IF(O5<=1000,0,IF(O5<=7500,0.05,0.18)))))/(IF(AND(N5>7500,O5>7500),N5/1.18,N5))) -> 0.74666028 | R5: =IF(OR(N5="",O5=""),"",((O5-N5)/1.18)/N5) -> 0.63276295 | S5: =IF(OR(P5="",O5=""),"",(P5-O5)/O5) -> -0.0041181669 | T5: =IF(AND(D5="",G5<>""),"no dates - assumed 1 night",IF(Q5="","",IF(Q5>1.5,"check: markup >150%",IF(Q5<0,"below cost",""))))
A6: Goa | B6: Fairfield by Marriott Goa Benaulim | C6: ~7d · mid-Jul | D6: 2026-08-13 | E6: 2026-08-16 | F6: =IF(OR(D6="",E6=""),1,MAX(1,DATEVALUE(E6)-DATEVALUE(D6))) -> 3 | G6: 21319 | H6: 22460 | L6: 235.43 | M6: 0.12 | N6: =IF(G6="","",G6/F6) -> 7106.3333 | O6: =IF(COUNT(H6:K6)=0,"",MIN(H6:K6)/F6) -> 7486.6667 | P6: =IF(L6="","",L6*95/F6) -> 7455.2833 | Q6: =IF(OR(N6="",O6=""),"",(IF(AND(N6>7500,O6>7500),O6/(1+IF(O6<=1000,0,IF(O6<=7500,0.05,0.18)))-IF(AND(N6>7500,O6>7500),N6/1.18,N6),(O6-IF(AND(N6>7500,O6>7500),N6/1.18,N6))/(1+IF(O6<=1000,0,IF(O6<=7500,0.05,0.18)))))/(IF(AND(N6>7500,O6>7500),N6/1.18,N6))) -> 0.050971747 | R6: =IF(OR(N6="",O6=""),"",((O6-N6)/1.18)/N6) -> 0.045356215 | S6: =IF(OR(P6="",O6=""),"",(P6-O6)/O6) -> -0.0041918967 | T6: =IF(AND(D6="",G6<>""),"no dates - assumed 1 night",IF(Q6="","",IF(Q6>1.5,"check: markup >150%",IF(Q6<0,"below cost",""))))
A7: Goa | B7: Fairfield by Marriott Goa Benaulim | C7: ~30d · mid-Aug | D7: 2026-08-28 | E7: 2026-08-31 | F7: =IF(OR(D7="",E7=""),1,MAX(1,DATEVALUE(E7)-DATEVALUE(D7))) -> 3 | G7: 20505 | H7: 22460 | L7: 217 | M7: 0.12 | N7: =IF(G7="","",G7/F7) -> 6835 | O7: =IF(COUNT(H7:K7)=0,"",MIN(H7:K7)/F7) -> 7486.6667 | P7: =IF(L7="","",L7*95/F7) -> 6871.6667 | Q7: =IF(OR(N7="",O7=""),"",(IF(AND(N7>7500,O7>7500),O7/(1+IF(O7<=1000,0,IF(O7<=7500,0.05,0.18)))-IF(AND(N7>7500,O7>7500),N7/1.18,N7),(O7-IF(AND(N7>7500,O7>7500),N7/1.18,N7))/(1+IF(O7<=1000,0,IF(O7<=7500,0.05,0.18)))))/(IF(AND(N7>7500,O7>7500),N7/1.18,N7))) -> 0.090802476 | R7: =IF(OR(N7="",O7=""),"",((O7-N7)/1.18)/N7) -> 0.080798813 | S7: =IF(OR(P7="",O7=""),"",(P7-O7)/O7) -> -0.082146037 | T7: =IF(AND(D7="",G7<>""),"no dates - assumed 1 night",IF(Q7="","",IF(Q7>1.5,"check: markup >150%",IF(Q7<0,"below cost",""))))
A8: Goa | B8: Fairfield by Marriott Goa Benaulim | C8: mid-Oct · Diwali | D8: 2026-11-12 | E8: 2026-11-15 | F8: =IF(OR(D8="",E8=""),1,MAX(1,DATEVALUE(E8)-DATEVALUE(D8))) -> 3 | G8: 42828 | H8: 44055 | L8: 461.83 | M8: 0.12 | N8: =IF(G8="","",G8/F8) -> 14276 | O8: =IF(COUNT(H8:K8)=0,"",MIN(H8:K8)/F8) -> 14685 | P8: =IF(L8="","",L8*95/F8) -> 14624.617 | Q8: =IF(OR(N8="",O8=""),"",(IF(AND(N8>7500,O8>7500),O8/(1+IF(O8<=1000,0,IF(O8<=7500,0.05,0.18)))-IF(AND(N8>7500,O8>7500),N8/1.18,N8),(O8-IF(AND(N8>7500,O8>7500),N8/1.18,N8))/(1+IF(O8<=1000,0,IF(O8<=7500,0.05,0.18)))))/(IF(AND(N8>7500,O8>7500),N8/1.18,N8))) -> 0.028649482 | R8: =IF(OR(N8="",O8=""),"",((O8-N8)/1.18)/N8) -> 0.024279222 | S8: =IF(OR(P8="",O8=""),"",(P8-O8)/O8) -> -0.0041119056 | T8: =IF(AND(D8="",G8<>""),"no dates - assumed 1 night",IF(Q8="","",IF(Q8>1.5,"check: markup >150%",IF(Q8<0,"below cost",""))))
A9: Goa | B9: Fairfield by Marriott Goa Benaulim | C9: 27–30 Dec | D9: 2026-12-29 | E9: 2027-01-01 | F9: =IF(OR(D9="",E9=""),1,MAX(1,DATEVALUE(E9)-DATEVALUE(D9))) -> 3 | G9: 56107 | H9: 58410 | L9: 612.31 | M9: 0.12 | N9: =IF(G9="","",G9/F9) -> 18702.333 | O9: =IF(COUNT(H9:K9)=0,"",MIN(H9:K9)/F9) -> 19470 | P9: =IF(L9="","",L9*95/F9) -> 19389.817 | Q9: =IF(OR(N9="",O9=""),"",(IF(AND(N9>7500,O9>7500),O9/(1+IF(O9<=1000,0,IF(O9<=7500,0.05,0.18)))-IF(AND(N9>7500,O9>7500),N9/1.18,N9),(O9-IF(AND(N9>7500,O9>7500),N9/1.18,N9))/(1+IF(O9<=1000,0,IF(O9<=7500,0.05,0.18)))))/(IF(AND(N9>7500,O9>7500),N9/1.18,N9))) -> 0.041046572 | R9: =IF(OR(N9="",O9=""),"",((O9-N9)/1.18)/N9) -> 0.03478523 | S9: =IF(OR(P9="",O9=""),"",(P9-O9)/O9) -> -0.0041183017 | T9: =IF(AND(D9="",G9<>""),"no dates - assumed 1 night",IF(Q9="","",IF(Q9>1.5,"check: markup >150%",IF(Q9<0,"below cost",""))))
A10: Goa | B10: Fairfield by Marriott Goa Benaulim | C10: mid-Feb | D10: 2027-02-11 | E10: 2027-02-14 | F10: =IF(OR(D10="",E10=""),1,MAX(1,DATEVALUE(E10)-DATEVALUE(D10))) -> 3 | G10: 61890 | H10: 66700 | L10: 678.68 | M10: 0.06 | N10: =IF(G10="","",G10/F10) -> 20630 | O10: =IF(COUNT(H10:K10)=0,"",MIN(H10:K10)/F10) -> 22233.333 | P10: =IF(L10="","",L10*95/F10) -> 21491.533 | Q10: =IF(OR(N10="",O10=""),"",(IF(AND(N10>7500,O10>7500),O10/(1+IF(O10<=1000,0,IF(O10<=7500,0.05,0.18)))-IF(AND(N10>7500,O10>7500),N10/1.18,N10),(O10-IF(AND(N10>7500,O10>7500),N10/1.18,N10))/(1+IF(O10<=1000,0,IF(O10<=7500,0.05,0.18)))))/(IF(AND(N10>7500,O10>7500),N10/1.18,N10))) -> 0.077718533 | R10: =IF(OR(N10="",O10=""),"",((O10-N10)/1.18)/N10) -> 0.065863163 | S10: =IF(OR(P10="",O10=""),"",(P10-O10)/O10) -> -0.033364318 | T10: =IF(AND(D10="",G10<>""),"no dates - assumed 1 night",IF(Q10="","",IF(Q10>1.5,"check: markup >150%",IF(Q10<0,"below cost",""))))
A11: Goa | B11: Jasminn Hotel, Goa | C11: ~7d · mid-Jul | D11: 2026-08-13 | E11: 2026-08-16 | F11: =IF(OR(D11="",E11=""),1,MAX(1,DATEVALUE(E11)-DATEVALUE(D11))) -> 3 | G11: 10697 | H11: 12855 | L11: 150.28 | M11: 0.12 | N11: =IF(G11="","",G11/F11) -> 3565.6667 | O11: =IF(COUNT(H11:K11)=0,"",MIN(H11:K11)/F11) -> 4285 | P11: =IF(L11="","",L11*95/F11) -> 4758.8667 | Q11: =IF(OR(N11="",O11=""),"",(IF(AND(N11>7500,O11>7500),O11/(1+IF(O11<=1000,0,IF(O11<=7500,0.05,0.18)))-IF(AND(N11>7500,O11>7500),N11/1.18,N11),(O11-IF(AND(N11>7500,O11>7500),N11/1.18,N11))/(1+IF(O11<=1000,0,IF(O11<=7500,0.05,0.18)))))/(IF(AND(N11>7500,O11>7500),N11/1.18,N11))) -> 0.1921322 | R11: =IF(OR(N11="",O11=""),"",((O11-N11)/1.18)/N11) -> 0.17096509 | S11: =IF(OR(P11="",O11=""),"",(P11-O11)/O11) -> 0.11058732 | T11: =IF(AND(D11="",G11<>""),"no dates - assumed 1 night",IF(Q11="","",IF(Q11>1.5,"check: markup >150%",IF(Q11<0,"below cost",""))))
A12: Goa | B12: Jasminn Hotel, Goa | C12: ~30d · mid-Aug | D12: 2026-08-28 | E12: 2026-08-31 | F12: =IF(OR(D12="",E12=""),1,MAX(1,DATEVALUE(E12)-DATEVALUE(D12))) -> 3 | G12: 9607 | H12: 11656 | L12: 137.22 | M12: 0.12 | N12: =IF(G12="","",G12/F12) -> 3202.3333 | O12: =IF(COUNT(H12:K12)=0,"",MIN(H12:K12)/F12) -> 3885.3333 | P12: =IF(L12="","",L12*95/F12) -> 4345.3 | Q12: =IF(OR(N12="",O12=""),"",(IF(AND(N12>7500,O12>7500),O12/(1+IF(O12<=1000,0,IF(O12<=7500,0.05,0.18)))-IF(AND(N12>7500,O12>7500),N12/1.18,N12),(O12-IF(AND(N12>7500,O12>7500),N12/1.18,N12))/(1+IF(O12<=1000,0,IF(O12<=7500,0.05,0.18)))))/(IF(AND(N12>7500,O12>7500),N12/1.18,N12))) -> 0.2031257 | R12: =IF(OR(N12="",O12=""),"",((O12-N12)/1.18)/N12) -> 0.18074744 | S12: =IF(OR(P12="",O12=""),"",(P12-O12)/O12) -> 0.11838538 | T12: =IF(AND(D12="",G12<>""),"no dates - assumed 1 night",IF(Q12="","",IF(Q12>1.5,"check: markup >150%",IF(Q12<0,"below cost",""))))
A13: Goa | B13: Jasminn Hotel, Goa | C13: mid-Oct · Diwali | D13: 2026-11-12 | E13: 2026-11-15 | F13: =IF(OR(D13="",E13=""),1,MAX(1,DATEVALUE(E13)-DATEVALUE(D13))) -> 3 | G13: 20315 | H13: 26617 | L13: 282 | M13: 0.12 | N13: =IF(G13="","",G13/F13) -> 6771.6667 | O13: =IF(COUNT(H13:K13)=0,"",MIN(H13:K13)/F13) -> 8872.3333 | P13: =IF(L13="","",L13*95/F13) -> 8930 | Q13: =IF(OR(N13="",O13=""),"",(IF(AND(N13>7500,O13>7500),O13/(1+IF(O13<=1000,0,IF(O13<=7500,0.05,0.18)))-IF(AND(N13>7500,O13>7500),N13/1.18,N13),(O13-IF(AND(N13>7500,O13>7500),N13/1.18,N13))/(1+IF(O13<=1000,0,IF(O13<=7500,0.05,0.18)))))/(IF(AND(N13>7500,O13>7500),N13/1.18,N13))) -> 0.26289333 | R13: =IF(OR(N13="",O13=""),"",((O13-N13)/1.18)/N13) -> 0.26289333 | S13: =IF(OR(P13="",O13=""),"",(P13-O13)/O13) -> 0.0064996055 | T13: =IF(AND(D13="",G13<>""),"no dates - assumed 1 night",IF(Q13="","",IF(Q13>1.5,"check: markup >150%",IF(Q13<0,"below cost",""))))
... A20: Goa | B20: Novotel Goa Dona Sylvia Resort | C20: mid-Feb | D20: 2027-02-11 | E20: 2027-02-14 | F20: =IF(OR(D20="",E20=""),1,MAX(1,DATEVALUE(E20)-DATEVALUE(D20))) -> 3 | G20: 160516 | H20: 205916 | L20: 1839.24 | M20: 0.12 | N20: =IF(G20="","",G20/F20) -> 53505.333 | O20: =IF(COUNT(H20:K20)=0,"",MIN(H20:K20)/F20) -> 68638.667 | P20: =IF(L20="","",L20*95/F20) -> 58242.6 | Q20: =IF(OR(N20="",O20=""),"",(IF(AND(N20>7500,O20>7500),O20/(1+IF(O20<=1000,0,IF(O20<=7500,0.05,0.18)))-IF(AND(N20>7500,O20>7500),N20/1.18,N20),(O20-IF(AND(N20>7500,O20>7500),N20/1.18,N20))/(1+IF(O20<=1000,0,IF(O20<=7500,0.05,0.18)))))/(IF(AND(N20>7500,O20>7500),N20/1.18,N20))) -> 0.28283785 | R20: =IF(OR(N20="",O20=""),"",((O20-N20)/1.18)/N20) -> 0.23969309 | S20: =IF(OR(P20="",O20=""),"",(P20-O20)/O20) -> -0.15146079 | T20: =IF(AND(D20="",G20<>""),"no dates - assumed 1 night",IF(Q20="","",IF(Q20>1.5,"check: markup >150%",IF(Q20<0,"below cost",""))))
A21: Goa | B21: Taj Fort Aguada Resort & Spa, Goa | C21: ~7d · mid-Jul | D21: 2026-08-13 | E21: 2026-08-16 | F21: =IF(OR(D21="",E21=""),1,MAX(1,DATEVALUE(E21)-DATEVALUE(D21))) -> 3 | G21: 66638 | H21: 84553 | N21: =IF(G21="","",G21/F21) -> 22212.667 | O21: =IF(COUNT(H21:K21)=0,"",MIN(H21:K21)/F21) -> 28184.333 | P21: =IF(L21="","",L21*95/F21) | Q21: =IF(OR(N21="",O21=""),"",(IF(AND(N21>7500,O21>7500),O21/(1+IF(O21<=1000,0,IF(O21<=7500,0.05,0.18)))-IF(AND(N21>7500,O21>7500),N21/1.18,N21),(O21-IF(AND(N21>7500,O21>7500),N21/1.18,N21))/(1+IF(O21<=1000,0,IF(O21<=7500,0.05,0.18)))))/(IF(AND(N21>7500,O21>7500),N21/1.18,N21))) -> 0.2688406 | R21: =IF(OR(N21="",O21=""),"",((O21-N21)/1.18)/N21) -> 0.22783102 | S21: =IF(OR(P21="",O21=""),"",(P21-O21)/O21) | T21: =IF(AND(D21="",G21<>""),"no dates - assumed 1 night",IF(Q21="","",IF(Q21>1.5,"check: markup >150%",IF(Q21<0,"below cost",""))))
A22: Goa | B22: Taj Fort Aguada Resort & Spa, Goa | C22: ~30d · mid-Aug | D22: 2026-08-28 | E22: 2026-08-31 | F22: =IF(OR(D22="",E22=""),1,MAX(1,DATEVALUE(E22)-DATEVALUE(D22))) -> 3 | G22: 54451 | H22: 68440 | N22: =IF(G22="","",G22/F22) -> 18150.333 | O22: =IF(COUNT(H22:K22)=0,"",MIN(H22:K22)/F22) -> 22813.333 | P22: =IF(L22="","",L22*95/F22) | Q22: =IF(OR(N22="",O22=""),"",(IF(AND(N22>7500,O22>7500),O22/(1+IF(O22<=1000,0,IF(O22<=7500,0.05,0.18)))-IF(AND(N22>7500,O22>7500),N22/1.18,N22),(O22-IF(AND(N22>7500,O22>7500),N22/1.18,N22))/(1+IF(O22<=1000,0,IF(O22<=7500,0.05,0.18)))))/(IF(AND(N22>7500,O22>7500),N22/1.18,N22))) -> 0.25690988 | R22: =IF(OR(N22="",O22=""),"",((O22-N22)/1.18)/N22) -> 0.21772024 | S22: =IF(OR(P22="",O22=""),"",(P22-O22)/O22) | T22: =IF(AND(D22="",G22<>""),"no dates - assumed 1 night",IF(Q22="","",IF(Q22>1.5,"check: markup >150%",IF(Q22<0,"below cost",""))))
A23: Goa | B23: Taj Fort Aguada Resort & Spa, Goa | C23: mid-Oct · Diwali | D23: 2026-11-12 | E23: 2026-11-15 | F23: =IF(OR(D23="",E23=""),1,MAX(1,DATEVALUE(E23)-DATEVALUE(D23))) -> 3 | G23: 143111 | H23: 178953 | N23: =IF(G23="","",G23/F23) -> 47703.667 | O23: =IF(COUNT(H23:K23)=0,"",MIN(H23:K23)/F23) -> 59651 | P23: =IF(L23="","",L23*95/F23) | Q23: =IF(OR(N23="",O23=""),"",(IF(AND(N23>7500,O23>7500),O23/(1+IF(O23<=1000,0,IF(O23<=7500,0.05,0.18)))-IF(AND(N23>7500,O23>7500),N23/1.18,N23),(O23-IF(AND(N23>7500,O23>7500),N23/1.18,N23))/(1+IF(O23<=1000,0,IF(O23<=7500,0.05,0.18)))))/(IF(AND(N23>7500,O23>7500),N23/1.18,N23))) -> 0.25044895 | R23: =IF(OR(N23="",O23=""),"",((O23-N23)/1.18)/N23) -> 0.21224487 | S23: =IF(OR(P23="",O23=""),"",(P23-O23)/O23) | T23: =IF(AND(D23="",G23<>""),"no dates - assumed 1 night",IF(Q23="","",IF(Q23>1.5,"check: markup >150%",IF(Q23<0,"below cost",""))))
A24: Goa | B24: Taj Fort Aguada Resort & Spa, Goa | C24: 27–30 Dec | D24: 2026-12-29 | E24: 2027-01-01 | F24: =IF(OR(D24="",E24=""),1,MAX(1,DATEVALUE(E24)-DATEVALUE(D24))) -> 3 | G24: 269790 | H24: 342200 | N24: =IF(G24="","",G24/F24) -> 89930 | O24: =IF(COUNT(H24:K24)=0,"",MIN(H24:K24)/F24) -> 114066.67 | P24: =IF(L24="","",L24*95/F24) | Q24: =IF(OR(N24="",O24=""),"",(IF(AND(N24>7500,O24>7500),O24/(1+IF(O24<=1000,0,IF(O24<=7500,0.05,0.18)))-IF(AND(N24>7500,O24>7500),N24/1.18,N24),(O24-IF(AND(N24>7500,O24>7500),N24/1.18,N24))/(1+IF(O24<=1000,0,IF(O24<=7500,0.05,0.18)))))/(IF(AND(N24>7500,O24>7500),N24/1.18,N24))) -> 0.26839394 | R24: =IF(OR(N24="",O24=""),"",((O24-N24)/1.18)/N24) -> 0.22745249 | S24: =IF(OR(P24="",O24=""),"",(P24-O24)/O24) | T24: =IF(AND(D24="",G24<>""),"no dates - assumed 1 night",IF(Q24="","",IF(Q24>1.5,"check: markup >150%",IF(Q24<0,"below cost",""))))
A25: Goa | B25: Taj Fort Aguada Resort & Spa, Goa | C25: mid-Feb | D25: 2027-02-11 | E25: 2027-02-14 | F25: =IF(OR(D25="",E25=""),1,MAX(1,DATEVALUE(E25)-DATEVALUE(D25))) -> 3 | G25: 98648 | H25: 103840 | N25: =IF(G25="","",G25/F25) -> 32882.667 | O25: =IF(COUNT(H25:K25)=0,"",MIN(H25:K25)/F25) -> 34613.333 | P25: =IF(L25="","",L25*95/F25) | Q25: =IF(OR(N25="",O25=""),"",(IF(AND(N25>7500,O25>7500),O25/(1+IF(O25<=1000,0,IF(O25<=7500,0.05,0.18)))-IF(AND(N25>7500,O25>7500),N25/1.18,N25),(O25-IF(AND(N25>7500,O25>7500),N25/1.18,N25))/(1+IF(O25<=1000,0,IF(O25<=7500,0.05,0.18)))))/(IF(AND(N25>7500,O25>7500),N25/1.18,N25))) -> 0.052631579 | R25: =IF(OR(N25="",O25=""),"",((O25-N25)/1.18)/N25) -> 0.044603033 | S25: =IF(OR(P25="",O25=""),"",(P25-O25)/O25) | T25: =IF(AND(D25="",G25<>""),"no dates - assumed 1 night",IF(Q25="","",IF(Q25>1.5,"check: markup >150%",IF(Q25<0,"below cost",""))))
A26: Goa | B26: - Holiday Inn Resort | C26: ~7d · mid-Jul | D26: 2026-08-13 | E26: 2026-08-16 | F26: =IF(OR(D26="",E26=""),1,MAX(1,DATEVALUE(E26)-DATEVALUE(D26))) -> 3 | G26: 28403 | H26: 34863 | N26: =IF(G26="","",G26/F26) -> 9467.6667 | O26: =IF(COUNT(H26:K26)=0,"",MIN(H26:K26)/F26) -> 11621 | P26: =IF(L26="","",L26*95/F26) | Q26: =IF(OR(N26="",O26=""),"",(IF(AND(N26>7500,O26>7500),O26/(1+IF(O26<=1000,0,IF(O26<=7500,0.05,0.18)))-IF(AND(N26>7500,O26>7500),N26/1.18,N26),(O26-IF(AND(N26>7500,O26>7500),N26/1.18,N26))/(1+IF(O26<=1000,0,IF(O26<=7500,0.05,0.18)))))/(IF(AND(N26>7500,O26>7500),N26/1.18,N26))) -> 0.22744076 | R26: =IF(OR(N26="",O26=""),"",((O26-N26)/1.18)/N26) -> 0.19274641 | S26: =IF(OR(P26="",O26=""),"",(P26-O26)/O26) | T26: =IF(AND(D26="",G26<>""),"no dates - assumed 1 night",IF(Q26="","",IF(Q26>1.5,"check: markup >150%",IF(Q26<0,"below cost",""))))
A27: Goa | B27: - Holiday Inn Resort | C27: ~30d · mid-Aug | D27: 2026-08-28 | E27: 2026-08-31 | F27: =IF(OR(D27="",E27=""),1,MAX(1,DATEVALUE(E27)-DATEVALUE(D27))) -> 3 | G27: 29886 | H27: 36685 | N27: =IF(G27="","",G27/F27) -> 9962 | O27: =IF(COUNT(H27:K27)=0,"",MIN(H27:K27)/F27) -> 12228.333 | P27: =IF(L27="","",L27*95/F27) | Q27: =IF(OR(N27="",O27=""),"",(IF(AND(N27>7500,O27>7500),O27/(1+IF(O27<=1000,0,IF(O27<=7500,0.05,0.18)))-IF(AND(N27>7500,O27>7500),N27/1.18,N27),(O27-IF(AND(N27>7500,O27>7500),N27/1.18,N27))/(1+IF(O27<=1000,0,IF(O27<=7500,0.05,0.18)))))/(IF(AND(N27>7500,O27>7500),N27/1.18,N27))) -> 0.22749783 | R27: =IF(OR(N27="",O27=""),"",((O27-N27)/1.18)/N27) -> 0.19279477 | S27: =IF(OR(P27="",O27=""),"",(P27-O27)/O27) | T27: =IF(AND(D27="",G27<>""),"no dates - assumed 1 night",IF(Q27="","",IF(Q27>1.5,"check: markup >150%",IF(Q27<0,"below cost",""))))
A28: Goa | B28: - Holiday Inn Resort | C28: mid-Oct · Diwali | D28: 2026-11-12 | E28: 2026-11-15 | F28: =IF(OR(D28="",E28=""),1,MAX(1,DATEVALUE(E28)-DATEVALUE(D28))) -> 3 | G28: 38267 | H28: 47896 | N28: =IF(G28="","",G28/F28) -> 12755.667 | O28: =IF(COUNT(H28:K28)=0,"",MIN(H28:K28)/F28) -> 15965.333 | P28: =IF(L28="","",L28*95/F28) | Q28: =IF(OR(N28="",O28=""),"",(IF(AND(N28>7500,O28>7500),O28/(1+IF(O28<=1000,0,IF(O28<=7500,0.05,0.18)))-IF(AND(N28>7500,O28>7500),N28/1.18,N28),(O28-IF(AND(N28>7500,O28>7500),N28/1.18,N28))/(1+IF(O28<=1000,0,IF(O28<=7500,0.05,0.18)))))/(IF(AND(N28>7500,O28>7500),N28/1.18,N28))) -> 0.25162673 | R28: =IF(OR(N28="",O28=""),"",((O28-N28)/1.18)/N28) -> 0.21324299 | S28: =IF(OR(P28="",O28=""),"",(P28-O28)/O28) | T28: =IF(AND(D28="",G28<>""),"no dates - assumed 1 night",IF(Q28="","",IF(Q28>1.5,"check: markup >150%",IF(Q28<0,"below cost",""))))
A29: Goa | B29: - Holiday Inn Resort | C29: mid-Feb | D29: 2027-02-11 | E29: 2027-02-14 | F29: =IF(OR(D29="",E29=""),1,MAX(1,DATEVALUE(E29)-DATEVALUE(D29))) -> 3 | G29: 99895 | H29: 125009 | N29: =IF(G29="","",G29/F29) -> 33298.333 | O29: =IF(COUNT(H29:K29)=0,"",MIN(H29:K29)/F29) -> 41669.667 | P29: =IF(L29="","",L29*95/F29) | Q29: =IF(OR(N29="",O29=""),"",(IF(AND(N29>7500,O29>7500),O29/(1+IF(O29<=1000,0,IF(O29<=7500,0.05,0.18)))-IF(AND(N29>7500,O29>7500),N29/1.18,N29),(O29-IF(AND(N29>7500,O29>7500),N29/1.18,N29))/(1+IF(O29<=1000,0,IF(O29<=7500,0.05,0.18)))))/(IF(AND(N29>7500,O29>7500),N29/1.18,N29))) -> 0.25140397 | R29: =IF(OR(N29="",O29=""),"",((O29-N29)/1.18)/N29) -> 0.21305422 | S29: =IF(OR(P29="",O29=""),"",(P29-O29)/O29) | T29: =IF(AND(D29="",G29<>""),"no dates - assumed 1 night",IF(Q29="","",IF(Q29>1.5,"check: markup >150%",IF(Q29<0,"below cost",""))))
A30: Goa | B30: - Hyatt Centric Candolim Goa | C30: ~7d · mid-Jul | D30: 2026-08-13 | E30: 2026-08-16 | F30: =IF(OR(D30="",E30=""),1,MAX(1,DATEVALUE(E30)-DATEVALUE(D30))) -> 3 | G30: 32860 | H30: 34011 | L30: 336.99 | M30: 0.12 | N30: =IF(G30="","",G30/F30) -> 10953.333 | O30: =IF(COUNT(H30:K30)=0,"",MIN(H30:K30)/F30) -> 11337 | P30: =IF(L30="","",L30*95/F30) -> 10671.35 | Q30: =IF(OR(N30="",O30=""),"",(IF(AND(N30>7500,O30>7500),O30/(1+IF(O30<=1000,0,IF(O30<=7500,0.05,0.18)))-IF(AND(N30>7500,O30>7500),N30/1.18,N30),(O30-IF(AND(N30>7500,O30>7500),N30/1.18,N30))/(1+IF(O30<=1000,0,IF(O30<=7500,0.05,0.18)))))/(IF(AND(N30>7500,O30>7500),N30/1.18,N30))) -> 0.035027389 | R30: =IF(OR(N30="",O30=""),"",((O30-N30)/1.18)/N30) -> 0.029684228 | S30: =IF(OR(P30="",O30=""),"",(P30-O30)/O30) -> -0.058714828 | T30: =IF(AND(D30="",G30<>""),"no dates - assumed 1 night",IF(Q30="","",IF(Q30>1.5,"check: markup >150%",IF(Q30<0,"below cost",""))))
A31: Goa | B31: - Hyatt Centric Candolim Goa | C31: ~30d · mid-Aug | D31: 2026-08-28 | E31: 2026-08-31 | F31: =IF(OR(D31="",E31=""),1,MAX(1,DATEVALUE(E31)-DATEVALUE(D31))) -> 3 | G31: 23153 | H31: 27320 | L31: 238.08 | M31: 0.12 | N31: =IF(G31="","",G31/F31) -> 7717.6667 | O31: =IF(COUNT(H31:K31)=0,"",MIN(H31:K31)/F31) -> 9106.6667 | P31: =IF(L31="","",L31*95/F31) -> 7539.2 | Q31: =IF(OR(N31="",O31=""),"",(IF(AND(N31>7500,O31>7500),O31/(1+IF(O31<=1000,0,IF(O31<=7500,0.05,0.18)))-IF(AND(N31>7500,O31>7500),N31/1.18,N31),(O31-IF(AND(N31>7500,O31>7500),N31/1.18,N31))/(1+IF(O31<=1000,0,IF(O31<=7500,0.05,0.18)))))/(IF(AND(N31>7500,O31>7500),N31/1.18,N31))) -> 0.17997668 | R31: =IF(OR(N31="",O31=""),"",((O31-N31)/1.18)/N31) -> 0.15252261 | S31: =IF(OR(P31="",O31=""),"",(P31-O31)/O31) -> -0.17212299 | T31: =IF(AND(D31="",G31<>""),"no dates - assumed 1 night",IF(Q31="","",IF(Q31>1.5,"check: markup >150%",IF(Q31<0,"below cost",""))))
A32: Goa | B32: - Hyatt Centric Candolim Goa | C32: mid-Oct · Diwali | D32: 2026-11-12 | E32: 2026-11-15 | F32: =IF(OR(D32="",E32=""),1,MAX(1,DATEVALUE(E32)-DATEVALUE(D32))) -> 3 | G32: 36313 | H32: 41259 | L32: 408.78 | M32: 0.12 | N32: =IF(G32="","",G32/F32) -> 12104.333 | O32: =IF(COUNT(H32:K32)=0,"",MIN(H32:K32)/F32) -> 13753 | P32: =IF(L32="","",L32*95/F32) -> 12944.7 | Q32: =IF(OR(N32="",O32=""),"",(IF(AND(N32>7500,O32>7500),O32/(1+IF(O32<=1000,0,IF(O32<=7500,0.05,0.18)))-IF(AND(N32>7500,O32>7500),N32/1.18,N32),(O32-IF(AND(N32>7500,O32>7500),N32/1.18,N32))/(1+IF(O32<=1000,0,IF(O32<=7500,0.05,0.18)))))/(IF(AND(N32>7500,O32>7500),N32/1.18,N32))) -> 0.13620466 | R32: =IF(OR(N32="",O32=""),"",((O32-N32)/1.18)/N32) -> 0.11542768 | S32: =IF(OR(P32="",O32=""),"",(P32-O32)/O32) -> -0.058772631 | T32: =IF(AND(D32="",G32<>""),"no dates - assumed 1 night",IF(Q32="","",IF(Q32>1.5,"check: markup >150%",IF(Q32<0,"below cost",""))))
A33: Goa | B33: - Hyatt Centric Candolim Goa | C33: 27–30 Dec | D33: 2026-12-29 | E33: 2027-01-01 | F33: =IF(OR(D33="",E33=""),1,MAX(1,DATEVALUE(E33)-DATEVALUE(D33))) -> 3 | G33: 82183 | H33: 83633 | L33: 828.63 | M33: 0.12 | N33: =IF(G33="","",G33/F33) -> 27394.333 | O33: =IF(COUNT(H33:K33)=0,"",MIN(H33:K33)/F33) -> 27877.667 | P33: =IF(L33="","",L33*95/F33) -> 26239.95 | Q33: =IF(OR(N33="",O33=""),"",(IF(AND(N33>7500,O33>7500),O33/(1+IF(O33<=1000,0,IF(O33<=7500,0.05,0.18)))-IF(AND(N33>7500,O33>7500),N33/1.18,N33),(O33-IF(AND(N33>7500,O33>7500),N33/1.18,N33))/(1+IF(O33<=1000,0,IF(O33<=7500,0.05,0.18)))))/(IF(AND(N33>7500,O33>7500),N33/1.18,N33))) -> 0.017643552 | R33: =IF(OR(N33="",O33=""),"",((O33-N33)/1.18)/N33) -> 0.014952162 | S33: =IF(OR(P33="",O33=""),"",(P33-O33)/O33) -> -0.058746547 | T33: =IF(AND(D33="",G33<>""),"no dates - assumed 1 night",IF(Q33="","",IF(Q33>1.5,"check: markup >150%",IF(Q33<0,"below cost",""))))
A34: Goa | B34: - Hyatt Centric Candolim Goa | C34: mid-Feb | D34: 2027-02-11 | E34: 2027-02-14 | F34: =IF(OR(D34="",E34=""),1,MAX(1,DATEVALUE(E34)-DATEVALUE(D34))) -> 3 | G34: 26979 | H34: 30665 | L34: 306.15 | M34: 0.12 | N34: =IF(G34="","",G34/F34) -> 8993 | O34: =IF(COUNT(H34:K34)=0,"",MIN(H34:K34)/F34) -> 10221.667 | P34: =IF(L34="","",L34*95/F34) -> 9694.75 | Q34: =IF(OR(N34="",O34=""),"",(IF(AND(N34>7500,O34>7500),O34/(1+IF(O34<=1000,0,IF(O34<=7500,0.05,0.18)))-IF(AND(N34>7500,O34>7500),N34/1.18,N34),(O34-IF(AND(N34>7500,O34>7500),N34/1.18,N34))/(1+IF(O34<=1000,0,IF(O34<=7500,0.05,0.18)))))/(IF(AND(N34>7500,O34>7500),N34/1.18,N34))) -> 0.13662478 | R34: =IF(OR(N34="",O34=""),"",((O34-N34)/1.18)/N34) -> 0.11578371 | S34: =IF(OR(P34="",O34=""),"",(P34-O34)/O34) -> -0.051548997 | T34: =IF(AND(D34="",G34<>""),"no dates - assumed 1 night",IF(Q34="","",IF(Q34>1.5,"check: markup >150%",IF(Q34<0,"below cost",""))))
A35: Goa | B35: - ITC Grand Goa - A Luxury Collection Resort | C35: ~7d · mid-Jul | D35: 2026-08-13 | E35: 2026-08-16 | F35: =IF(OR(D35="",E35=""),1,MAX(1,DATEVALUE(E35)-DATEVALUE(D35))) -> 3 | G35: 68959 | H35: 83072 | N35: =IF(G35="","",G35/F35) -> 22986.333 | O35: =IF(COUNT(H35:K35)=0,"",MIN(H35:K35)/F35) -> 27690.667 | P35: =IF(L35="","",L35*95/F35) | Q35: =IF(OR(N35="",O35=""),"",(IF(AND(N35>7500,O35>7500),O35/(1+IF(O35<=1000,0,IF(O35<=7500,0.05,0.18)))-IF(AND(N35>7500,O35>7500),N35/1.18,N35),(O35-IF(AND(N35>7500,O35>7500),N35/1.18,N35))/(1+IF(O35<=1000,0,IF(O35<=7500,0.05,0.18)))))/(IF(AND(N35>7500,O35>7500),N35/1.18,N35))) -> 0.20465784 | R35: =IF(OR(N35="",O35=""),"",((O35-N35)/1.18)/N35) -> 0.17343885 | S35: =IF(OR(P35="",O35=""),"",(P35-O35)/O35) | T35: =IF(AND(D35="",G35<>""),"no dates - assumed 1 night",IF(Q35="","",IF(Q35>1.5,"check: markup >150%",IF(Q35<0,"below cost",""))))
A36: Goa | B36: - ITC Grand Goa - A Luxury Collection Resort | C36: mid-Oct · Diwali | D36: 2026-11-12 | E36: 2026-11-15 | F36: =IF(OR(D36="",E36=""),1,MAX(1,DATEVALUE(E36)-DATEVALUE(D36))) -> 3 | G36: 80544 | H36: 100890 | N36: =IF(G36="","",G36/F36) -> 26848 | O36: =IF(COUNT(H36:K36)=0,"",MIN(H36:K36)/F36) -> 33630 | P36: =IF(L36="","",L36*95/F36) | Q36: =IF(OR(N36="",O36=""),"",(IF(AND(N36>7500,O36>7500),O36/(1+IF(O36<=1000,0,IF(O36<=7500,0.05,0.18)))-IF(AND(N36>7500,O36>7500),N36/1.18,N36),(O36-IF(AND(N36>7500,O36>7500),N36/1.18,N36))/(1+IF(O36<=1000,0,IF(O36<=7500,0.05,0.18)))))/(IF(AND(N36>7500,O36>7500),N36/1.18,N36))) -> 0.25260727 | R36: =IF(OR(N36="",O36=""),"",((O36-N36)/1.18)/N36) -> 0.21407396 | S36: =IF(OR(P36="",O36=""),"",(P36-O36)/O36) | T36: =IF(AND(D36="",G36<>""),"no dates - assumed 1 night",IF(Q36="","",IF(Q36>1.5,"check: markup >150%",IF(Q36<0,"below cost",""))))
A37: Goa | B37: - ITC Grand Goa - A Luxury Collection Resort | C37: 27–30 Dec | D37: 2026-12-29 | E37: 2027-01-31 | F37: =IF(OR(D37="",E37=""),1,MAX(1,DATEVALUE(E37)-DATEVALUE(D37))) -> 33 | G37: 184869 | H37: 170375 | N37: =IF(G37="","",G37/F37) -> 5602.0909 | O37: =IF(COUNT(H37:K37)=0,"",MIN(H37:K37)/F37) -> 5162.8788 | P37: =IF(L37="","",L37*95/F37) | Q37: =IF(OR(N37="",O37=""),"",(IF(AND(N37>7500,O37>7500),O37/(1+IF(O37<=1000,0,IF(O37<=7500,0.05,0.18)))-IF(AND(N37>7500,O37>7500),N37/1.18,N37),(O37-IF(AND(N37>7500,O37>7500),N37/1.18,N37))/(1+IF(O37<=1000,0,IF(O37<=7500,0.05,0.18)))))/(IF(AND(N37>7500,O37>7500),N37/1.18,N37))) -> -0.07466806 | R37: =IF(OR(N37="",O37=""),"",((O37-N37)/1.18)/N37) -> -0.066441918 | S37: =IF(OR(P37="",O37=""),"",(P37-O37)/O37) | T37: =IF(AND(D37="",G37<>""),"no dates - assumed 1 night",IF(Q37="","",IF(Q37>1.5,"check: markup >150%",IF(Q37<0,"below cost","")))) -> below cost
A38: Goa | B38: - ITC Grand Goa - A Luxury Collection Resort | C38: mid-Feb | D38: 2027-02-11 | E38: 2027-02-14 | F38: =IF(OR(D38="",E38=""),1,MAX(1,DATEVALUE(E38)-DATEVALUE(D38))) -> 3 | G38: 123499 | H38: 154698 | N38: =IF(G38="","",G38/F38) -> 41166.333 | O38: =IF(COUNT(H38:K38)=0,"",MIN(H38:K38)/F38) -> 51566 | P38: =IF(L38="","",L38*95/F38) | Q38: =IF(OR(N38="",O38=""),"",(IF(AND(N38>7500,O38>7500),O38/(1+IF(O38<=1000,0,IF(O38<=7500,0.05,0.18)))-IF(AND(N38>7500,O38>7500),N38/1.18,N38),(O38-IF(AND(N38>7500,O38>7500),N38/1.18,N38))/(1+IF(O38<=1000,0,IF(O38<=7500,0.05,0.18)))))/(IF(AND(N38>7500,O38>7500),N38/1.18,N38))) -> 0.25262553 | R38: =IF(OR(N38="",O38=""),"",((O38-N38)/1.18)/N38) -> 0.21408943 | S38: =IF(OR(P38="",O38=""),"",(P38-O38)/O38) | T38: =IF(AND(D38="",G38<>""),"no dates - assumed 1 night",IF(Q38="","",IF(Q38>1.5,"check: markup >150%",IF(Q38<0,"below cost",""))))
A39: Goa | B39: - Le Meridien Goa, Calangute | C39: ~7d · mid-Jul | D39: 2026-08-13 | E39: 2026-08-16 | F39: =IF(OR(D39="",E39=""),1,MAX(1,DATEVALUE(E39)-DATEVALUE(D39))) -> 3 | G39: 34996 | H39: 37554 | L39: 381.94 | M39: 0.12 | N39: =IF(G39="","",G39/F39) -> 11665.333 | O39: =IF(COUNT(H39:K39)=0,"",MIN(H39:K39)/F39) -> 12518 | P39: =IF(L39="","",L39*95/F39) -> 12094.767 | Q39: =IF(OR(N39="",O39=""),"",(IF(AND(N39>7500,O39>7500),O39/(1+IF(O39<=1000,0,IF(O39<=7500,0.05,0.18)))-IF(AND(N39>7500,O39>7500),N39/1.18,N39),(O39-IF(AND(N39>7500,O39>7500),N39/1.18,N39))/(1+IF(O39<=1000,0,IF(O39<=7500,0.05,0.18)))))/(IF(AND(N39>7500,O39>7500),N39/1.18,N39))) -> 0.073094068 | R39: =IF(OR(N39="",O39=""),"",((O39-N39)/1.18)/N39) -> 0.061944125 | S39: =IF(OR(P39="",O39=""),"",(P39-O39)/O39) -> -0.03380998 | T39: =IF(AND(D39="",G39<>""),"no dates - assumed 1 night",IF(Q39="","",IF(Q39>1.5,"check: markup >150%",IF(Q39<0,"below cost",""))))
A40: Goa | B40: - Le Meridien Goa, Calangute | C40: ~30d · mid-Aug | D40: 2026-08-28 | E40: 2026-08-31 | F40: =IF(OR(D40="",E40=""),1,MAX(1,DATEVALUE(E40)-DATEVALUE(D40))) -> 3 | G40: 26170 | H40: 27659 | L40: 289.94 | M40: 0.12 | N40: =IF(G40="","",G40/F40) -> 8723.3333 | O40: =IF(COUNT(H40:K40)=0,"",MIN(H40:K40)/F40) -> 9219.6667 | P40: =IF(L40="","",L40*95/F40) -> 9181.4333 | Q40: =IF(OR(N40="",O40=""),"",(IF(AND(N40>7500,O40>7500),O40/(1+IF(O40<=1000,0,IF(O40<=7500,0.05,0.18)))-IF(AND(N40>7500,O40>7500),N40/1.18,N40),(O40-IF(AND(N40>7500,O40>7500),N40/1.18,N40))/(1+IF(O40<=1000,0,IF(O40<=7500,0.05,0.18)))))/(IF(AND(N40>7500,O40>7500),N40/1.18,N40))) -> 0.056897211 | R40: =IF(OR(N40="",O40=""),"",((O40-N40)/1.18)/N40) -> 0.048217975 | S40: =IF(OR(P40="",O40=""),"",(P40-O40)/O40) -> -0.0041469323 | T40: =IF(AND(D40="",G40<>""),"no dates - assumed 1 night",IF(Q40="","",IF(Q40>1.5,"check: markup >150%",IF(Q40<0,"below cost",""))))
A41: Goa | B41: - Le Meridien Goa, Calangute | C41: mid-Oct · Diwali | D41: 2026-11-12 | E41: 2026-11-15 | F41: =IF(OR(D41="",E41=""),1,MAX(1,DATEVALUE(E41)-DATEVALUE(D41))) -> 3 | G41: 44473 | H41: 46522 | L41: 487.68 | M41: 0.12 | N41: =IF(G41="","",G41/F41) -> 14824.333 | O41: =IF(COUNT(H41:K41)=0,"",MIN(H41:K41)/F41) -> 15507.333 | P41: =IF(L41="","",L41*95/F41) -> 15443.2 | Q41: =IF(OR(N41="",O41=""),"",(IF(AND(N41>7500,O41>7500),O41/(1+IF(O41<=1000,0,IF(O41<=7500,0.05,0.18)))-IF(AND(N41>7500,O41>7500),N41/1.18,N41),(O41-IF(AND(N41>7500,O41>7500),N41/1.18,N41))/(1+IF(O41<=1000,0,IF(O41<=7500,0.05,0.18)))))/(IF(AND(N41>7500,O41>7500),N41/1.18,N41))) -> 0.046072898 | R41: =IF(OR(N41="",O41=""),"",((O41-N41)/1.18)/N41) -> 0.039044829 | S41: =IF(OR(P41="",O41=""),"",(P41-O41)/O41) -> -0.0041356777 | T41: =IF(AND(D41="",G41<>""),"no dates - assumed 1 night",IF(Q41="","",IF(Q41>1.5,"check: markup >150%",IF(Q41<0,"below cost",""))))
A42: Goa | B42: - Le Meridien Goa, Calangute | C42: 27–30 Dec | D42: 2026-12-29 | E42: 2027-01-01 | F42: =IF(OR(D42="",E42=""),1,MAX(1,DATEVALUE(E42)-DATEVALUE(D42))) -> 3 | G42: 70721 | H42: 79650 | L42: 834.97 | M42: 0.12 | N42: =IF(G42="","",G42/F42) -> 23573.667 | O42: =IF(COUNT(H42:K42)=0,"",MIN(H42:K42)/F42) -> 26550 | P42: =IF(L42="","",L42*95/F42) -> 26440.717 | Q42: =IF(OR(N42="",O42=""),"",(IF(AND(N42>7500,O42>7500),O42/(1+IF(O42<=1000,0,IF(O42<=7500,0.05,0.18)))-IF(AND(N42>7500,O42>7500),N42/1.18,N42),(O42-IF(AND(N42>7500,O42>7500),N42/1.18,N42))/(1+IF(O42<=1000,0,IF(O42<=7500,0.05,0.18)))))/(IF(AND(N42>7500,O42>7500),N42/1.18,N42))) -> 0.1262567 | R42: =IF(OR(N42="",O42=""),"",((O42-N42)/1.18)/N42) -> 0.1069972 | S42: =IF(OR(P42="",O42=""),"",(P42-O42)/O42) -> -0.0041161331 | T42: =IF(AND(D42="",G42<>""),"no dates - assumed 1 night",IF(Q42="","",IF(Q42>1.5,"check: markup >150%",IF(Q42<0,"below cost",""))))
A43: Goa | B43: - Le Meridien Goa, Calangute | C43: mid-Feb | D43: 2027-02-11 | E43: 2027-02-14 | F43: =IF(OR(D43="",E43=""),1,MAX(1,DATEVALUE(E43)-DATEVALUE(D43))) -> 3 | G43: 30389 | H43: 34191 | L43: 358.42 | M43: 0.12 | N43: =IF(G43="","",G43/F43) -> 10129.667 | O43: =IF(COUNT(H43:K43)=0,"",MIN(H43:K43)/F43) -> 11397 | P43: =IF(L43="","",L43*95/F43) -> 11349.967 | Q43: =IF(OR(N43="",O43=""),"",(IF(AND(N43>7500,O43>7500),O43/(1+IF(O43<=1000,0,IF(O43<=7500,0.05,0.18)))-IF(AND(N43>7500,O43>7500),N43/1.18,N43),(O43-IF(AND(N43>7500,O43>7500),N43/1.18,N43))/(1+IF(O43<=1000,0,IF(O43<=7500,0.05,0.18)))))/(IF(AND(N43>7500,O43>7500),N43/1.18,N43))) -> 0.12511106 | R43: =IF(OR(N43="",O43=""),"",((O43-N43)/1.18)/N43) -> 0.10602632 | S43: =IF(OR(P43="",O43=""),"",(P43-O43)/O43) -> -0.004126817 | T43: =IF(AND(D43="",G43<>""),"no dates - assumed 1 night",IF(Q43="","",IF(Q43>1.5,"check: markup >150%",IF(Q43<0,"below cost",""))))
A44: Goa | B44: - Marquis Beach Resort | C44: ~7d · mid-Jul | D44: 2026-08-13 | E44: 2026-08-16 | F44: =IF(OR(D44="",E44=""),1,MAX(1,DATEVALUE(E44)-DATEVALUE(D44))) -> 3 | G44: 38539 | H44: 40590 | N44: =IF(G44="","",G44/F44) -> 12846.333 | O44: =IF(COUNT(H44:K44)=0,"",MIN(H44:K44)/F44) -> 13530 | P44: =IF(L44="","",L44*95/F44) | Q44: =IF(OR(N44="",O44=""),"",(IF(AND(N44>7500,O44>7500),O44/(1+IF(O44<=1000,0,IF(O44<=7500,0.05,0.18)))-IF(AND(N44>7500,O44>7500),N44/1.18,N44),(O44-IF(AND(N44>7500,O44>7500),N44/1.18,N44))/(1+IF(O44<=1000,0,IF(O44<=7500,0.05,0.18)))))/(IF(AND(N44>7500,O44>7500),N44/1.18,N44))) -> 0.053218817 | R44: =IF(OR(N44="",O44=""),"",((O44-N44)/1.18)/N44) -> 0.045100693 | S44: =IF(OR(P44="",O44=""),"",(P44-O44)/O44) | T44: =IF(AND(D44="",G44<>""),"no dates - assumed 1 night",IF(Q44="","",IF(Q44>1.5,"check: markup >150%",IF(Q44<0,"below cost",""))))
A45: Goa | B45: - Marquis Beach Resort | C45: ~30d · mid-Aug | D45: 2026-08-28 | E45: 2026-08-31 | F45: =IF(OR(D45="",E45=""),1,MAX(1,DATEVALUE(E45)-DATEVALUE(D45))) -> 3 | G45: 31566 | H45: 33210 | N45: =IF(G45="","",G45/F45) -> 10522 | O45: =IF(COUNT(H45:K45)=0,"",MIN(H45:K45)/F45) -> 11070 | P45: =IF(L45="","",L45*95/F45) | Q45: =IF(OR(N45="",O45=""),"",(IF(AND(N45>7500,O45>7500),O45/(1+IF(O45<=1000,0,IF(O45<=7500,0.05,0.18)))-IF(AND(N45>7500,O45>7500),N45/1.18,N45),(O45-IF(AND(N45>7500,O45>7500),N45/1.18,N45))/(1+IF(O45<=1000,0,IF(O45<=7500,0.05,0.18)))))/(IF(AND(N45>7500,O45>7500),N45/1.18,N45))) -> 0.052081353 | R45: =IF(OR(N45="",O45=""),"",((O45-N45)/1.18)/N45) -> 0.04413674 | S45: =IF(OR(P45="",O45=""),"",(P45-O45)/O45) | T45: =IF(AND(D45="",G45<>""),"no dates - assumed 1 night",IF(Q45="","",IF(Q45>1.5,"check: markup >150%",IF(Q45<0,"below cost",""))))
A46: Goa | B46: - Marquis Beach Resort | C46: mid-Oct · Diwali | D46: 2026-11-12 | E46: 2026-11-15 | F46: =IF(OR(D46="",E46=""),1,MAX(1,DATEVALUE(E46)-DATEVALUE(D46))) -> 3 | G46: 31566 | H46: 33210 | N46: =IF(G46="","",G46/F46) -> 10522 | O46: =IF(COUNT(H46:K46)=0,"",MIN(H46:K46)/F46) -> 11070 | P46: =IF(L46="","",L46*95/F46) | Q46: =IF(OR(N46="",O46=""),"",(IF(AND(N46>7500,O46>7500),O46/(1+IF(O46<=1000,0,IF(O46<=7500,0.05,0.18)))-IF(AND(N46>7500,O46>7500),N46/1.18,N46),(O46-IF(AND(N46>7500,O46>7500),N46/1.18,N46))/(1+IF(O46<=1000,0,IF(O46<=7500,0.05,0.18)))))/(IF(AND(N46>7500,O46>7500),N46/1.18,N46))) -> 0.052081353 | R46: =IF(OR(N46="",O46=""),"",((O46-N46)/1.18)/N46) -> 0.04413674 | S46: =IF(OR(P46="",O46=""),"",(P46-O46)/O46) | T46: =IF(AND(D46="",G46<>""),"no dates - assumed 1 night",IF(Q46="","",IF(Q46>1.5,"check: markup >150%",IF(Q46<0,"below cost",""))))
...

Sheet Lonavala-Mahabaleshwar
A1: City | B1: Property | C1: Season slot | D1: Check-in | E1: Check-out | F1: Nights | G1: TBO (stay) | H1: MMT (stay) | I1: Goibibo (stay) | J1: Booking (stay) | K1: Agoda (stay) | L1: Rove ($) | M1: Return % | N1: TBO / night | O1: Cheapest OTA / night | P1: Rove / night (INR) | Q1: Markup % | R1: Agent % | S1: Rove mk % | T1: Flag
A2: Lonavala/Mahabaleshwar | B2: - 7 Apple Resort, Lonavala | C2: ~7d · mid-Jul | D2: 2026-08-14 | E2: 2026-08-16 | F2: =IF(OR(D2="",E2=""),1,MAX(1,DATEVALUE(E2)-DATEVALUE(D2))) -> 2 | G2: 21929 | H2: 25639 | N2: =IF(G2="","",G2/F2) -> 10964.5 | O2: =IF(COUNT(H2:K2)=0,"",MIN(H2:K2)/F2) -> 12819.5 | P2: =IF(L2="","",L2*95/F2) | Q2: =IF(OR(N2="",O2=""),"",(IF(AND(N2>7500,O2>7500),O2/(1+IF(O2<=1000,0,IF(O2<=7500,0.05,0.18)))-IF(AND(N2>7500,O2>7500),N2/1.18,N2),(O2-IF(AND(N2>7500,O2>7500),N2/1.18,N2))/(1+IF(O2<=1000,0,IF(O2<=7500,0.05,0.18)))))/(IF(AND(N2>7500,O2>7500),N2/1.18,N2))) -> 0.16918236 | R2: =IF(OR(N2="",O2=""),"",((O2-N2)/1.18)/N2) -> 0.14337488 | S2: =IF(OR(P2="",O2=""),"",(P2-O2)/O2) | T2: =IF(AND(D2="",G2<>""),"no dates - assumed 1 night",IF(Q2="","",IF(Q2>1.5,"check: markup >150%",IF(Q2<0,"below cost",""))))
A3: Lonavala/Mahabaleshwar | B3: - 7 Apple Resort, Lonavala | C3: ~30d · mid-Aug | D3: 2026-08-28 | E3: 2026-08-30 | F3: =IF(OR(D3="",E3=""),1,MAX(1,DATEVALUE(E3)-DATEVALUE(D3))) -> 2 | G3: 20872 | H3: 24341 | N3: =IF(G3="","",G3/F3) -> 10436 | O3: =IF(COUNT(H3:K3)=0,"",MIN(H3:K3)/F3) -> 12170.5 | P3: =IF(L3="","",L3*95/F3) | Q3: =IF(OR(N3="",O3=""),"",(IF(AND(N3>7500,O3>7500),O3/(1+IF(O3<=1000,0,IF(O3<=7500,0.05,0.18)))-IF(AND(N3>7500,O3>7500),N3/1.18,N3),(O3-IF(AND(N3>7500,O3>7500),N3/1.18,N3))/(1+IF(O3<=1000,0,IF(O3<=7500,0.05,0.18)))))/(IF(AND(N3>7500,O3>7500),N3/1.18,N3))) -> 0.16620353 | R3: =IF(OR(N3="",O3=""),"",((O3-N3)/1.18)/N3) -> 0.14085045 | S3: =IF(OR(P3="",O3=""),"",(P3-O3)/O3) | T3: =IF(AND(D3="",G3<>""),"no dates - assumed 1 night",IF(Q3="","",IF(Q3>1.5,"check: markup >150%",IF(Q3<0,"below cost",""))))
A4: Lonavala/Mahabaleshwar | B4: - 7 Apple Resort, Lonavala | C4: mid-Oct · Diwali | D4: 2026-09-05 | E4: 2026-09-06 | F4: =IF(OR(D4="",E4=""),1,MAX(1,DATEVALUE(E4)-DATEVALUE(D4))) -> 1 | G4: 10211 | H4: 11935 | N4: =IF(G4="","",G4/F4) -> 10211 | O4: =IF(COUNT(H4:K4)=0,"",MIN(H4:K4)/F4) -> 11935 | P4: =IF(L4="","",L4*95/F4) | Q4: =IF(OR(N4="",O4=""),"",(IF(AND(N4>7500,O4>7500),O4/(1+IF(O4<=1000,0,IF(O4<=7500,0.05,0.18)))-IF(AND(N4>7500,O4>7500),N4/1.18,N4),(O4-IF(AND(N4>7500,O4>7500),N4/1.18,N4))/(1+IF(O4<=1000,0,IF(O4<=7500,0.05,0.18)))))/(IF(AND(N4>7500,O4>7500),N4/1.18,N4))) -> 0.16883753 | R4: =IF(OR(N4="",O4=""),"",((O4-N4)/1.18)/N4) -> 0.14308265 | S4: =IF(OR(P4="",O4=""),"",(P4-O4)/O4) | T4: =IF(AND(D4="",G4<>""),"no dates - assumed 1 night",IF(Q4="","",IF(Q4>1.5,"check: markup >150%",IF(Q4<0,"below cost",""))))
A5: Lonavala/Mahabaleshwar | B5: - 7 Apple Resort, Lonavala | C5: 27–30 Dec | D5: 2026-09-12 | E5: 2026-09-13 | F5: =IF(OR(D5="",E5=""),1,MAX(1,DATEVALUE(E5)-DATEVALUE(D5))) -> 1 | G5: 9538 | H5: 10755 | N5: =IF(G5="","",G5/F5) -> 9538 | O5: =IF(COUNT(H5:K5)=0,"",MIN(H5:K5)/F5) -> 10755 | P5: =IF(L5="","",L5*95/F5) | Q5: =IF(OR(N5="",O5=""),"",(IF(AND(N5>7500,O5>7500),O5/(1+IF(O5<=1000,0,IF(O5<=7500,0.05,0.18)))-IF(AND(N5>7500,O5>7500),N5/1.18,N5),(O5-IF(AND(N5>7500,O5>7500),N5/1.18,N5))/(1+IF(O5<=1000,0,IF(O5<=7500,0.05,0.18)))))/(IF(AND(N5>7500,O5>7500),N5/1.18,N5))) -> 0.12759488 | R5: =IF(OR(N5="",O5=""),"",((O5-N5)/1.18)/N5) -> 0.10813126 | S5: =IF(OR(P5="",O5=""),"",(P5-O5)/O5) | T5: =IF(AND(D5="",G5<>""),"no dates - assumed 1 night",IF(Q5="","",IF(Q5>1.5,"check: markup >150%",IF(Q5<0,"below cost",""))))
A6: Lonavala/Mahabaleshwar | B6: - Arova Woods Zinc Journey by The Fern, Lonavala | C6: ~30d · mid-Aug | D6: 2026-08-28 | E6: 2026-08-30 | F6: =IF(OR(D6="",E6=""),1,MAX(1,DATEVALUE(E6)-DATEVALUE(D6))) -> 2 | G6: 24214 | H6: 22123 | N6: =IF(G6="","",G6/F6) -> 12107 | O6: =IF(COUNT(H6:K6)=0,"",MIN(H6:K6)/F6) -> 11061.5 | P6: =IF(L6="","",L6*95/F6) | Q6: =IF(OR(N6="",O6=""),"",(IF(AND(N6>7500,O6>7500),O6/(1+IF(O6<=1000,0,IF(O6<=7500,0.05,0.18)))-IF(AND(N6>7500,O6>7500),N6/1.18,N6),(O6-IF(AND(N6>7500,O6>7500),N6/1.18,N6))/(1+IF(O6<=1000,0,IF(O6<=7500,0.05,0.18)))))/(IF(AND(N6>7500,O6>7500),N6/1.18,N6))) -> -0.086355001 | R6: =IF(OR(N6="",O6=""),"",((O6-N6)/1.18)/N6) -> -0.073182204 | S6: =IF(OR(P6="",O6=""),"",(P6-O6)/O6) | T6: =IF(AND(D6="",G6<>""),"no dates - assumed 1 night",IF(Q6="","",IF(Q6>1.5,"check: markup >150%",IF(Q6<0,"below cost","")))) -> below cost
A7: Lonavala/Mahabaleshwar | B7: - Arova Woods Zinc Journey by The Fern, Lonavala | C7: mid-Oct · Diwali | D7: 2026-09-05 | E7: 2026-09-06 | F7: =IF(OR(D7="",E7=""),1,MAX(1,DATEVALUE(E7)-DATEVALUE(D7))) -> 1 | G7: 13721 | H7: 13717 | N7: =IF(G7="","",G7/F7) -> 13721 | O7: =IF(COUNT(H7:K7)=0,"",MIN(H7:K7)/F7) -> 13717 | P7: =IF(L7="","",L7*95/F7) | Q7: =IF(OR(N7="",O7=""),"",(IF(AND(N7>7500,O7>7500),O7/(1+IF(O7<=1000,0,IF(O7<=7500,0.05,0.18)))-IF(AND(N7>7500,O7>7500),N7/1.18,N7),(O7-IF(AND(N7>7500,O7>7500),N7/1.18,N7))/(1+IF(O7<=1000,0,IF(O7<=7500,0.05,0.18)))))/(IF(AND(N7>7500,O7>7500),N7/1.18,N7))) -> -0.00029152394 | R7: =IF(OR(N7="",O7=""),"",((O7-N7)/1.18)/N7) -> -0.00024705419 | S7: =IF(OR(P7="",O7=""),"",(P7-O7)/O7) | T7: =IF(AND(D7="",G7<>""),"no dates - assumed 1 night",IF(Q7="","",IF(Q7>1.5,"check: markup >150%",IF(Q7<0,"below cost","")))) -> below cost
A8: Lonavala/Mahabaleshwar | B8: - Arova Woods Zinc Journey by The Fern, Lonavala | C8: 27–30 Dec | D8: 2026-09-12 | E8: 2026-09-13 | F8: =IF(OR(D8="",E8=""),1,MAX(1,DATEVALUE(E8)-DATEVALUE(D8))) -> 1 | G8: 12914 | H8: 11947 | N8: =IF(G8="","",G8/F8) -> 12914 | O8: =IF(COUNT(H8:K8)=0,"",MIN(H8:K8)/F8) -> 11947 | P8: =IF(L8="","",L8*95/F8) | Q8: =IF(OR(N8="",O8=""),"",(IF(AND(N8>7500,O8>7500),O8/(1+IF(O8<=1000,0,IF(O8<=7500,0.05,0.18)))-IF(AND(N8>7500,O8>7500),N8/1.18,N8),(O8-IF(AND(N8>7500,O8>7500),N8/1.18,N8))/(1+IF(O8<=1000,0,IF(O8<=7500,0.05,0.18)))))/(IF(AND(N8>7500,O8>7500),N8/1.18,N8))) -> -0.074879975 | R8: =IF(OR(N8="",O8=""),"",((O8-N8)/1.18)/N8) -> -0.063457606 | S8: =IF(OR(P8="",O8=""),"",(P8-O8)/O8) | T8: =IF(AND(D8="",G8<>""),"no dates - assumed 1 night",IF(Q8="","",IF(Q8>1.5,"check: markup >150%",IF(Q8<0,"below cost","")))) -> below cost
A9: Lonavala/Mahabaleshwar | B9: - Arova Woods Zinc Journey by The Fern, Lonavala | C9: mid-Feb | D9: 2026-08-21 | E9: 2026-08-23 | F9: =IF(OR(D9="",E9=""),1,MAX(1,DATEVALUE(E9)-DATEVALUE(D9))) -> 2 | G9: 26190 | H9: 24070 | N9: =IF(G9="","",G9/F9) -> 13095 | O9: =IF(COUNT(H9:K9)=0,"",MIN(H9:K9)/F9) -> 12035 | P9: =IF(L9="","",L9*95/F9) | Q9: =IF(OR(N9="",O9=""),"",(IF(AND(N9>7500,O9>7500),O9/(1+IF(O9<=1000,0,IF(O9<=7500,0.05,0.18)))-IF(AND(N9>7500,O9>7500),N9/1.18,N9),(O9-IF(AND(N9>7500,O9>7500),N9/1.18,N9))/(1+IF(O9<=1000,0,IF(O9<=7500,0.05,0.18)))))/(IF(AND(N9>7500,O9>7500),N9/1.18,N9))) -> -0.080946926 | R9: =IF(OR(N9="",O9=""),"",((O9-N9)/1.18)/N9) -> -0.06859909 | S9: =IF(OR(P9="",O9=""),"",(P9-O9)/O9) | T9: =IF(AND(D9="",G9<>""),"no dates - assumed 1 night",IF(Q9="","",IF(Q9>1.5,"check: markup >150%",IF(Q9<0,"below cost","")))) -> below cost
A10: Lonavala/Mahabaleshwar | B10: - Athiva Resort & Spa Khandala (Formerly Dukes Retreat) | C10: ~7d · mid-Jul | D10: 2026-08-14 | E10: 2026-08-16 | F10: =IF(OR(D10="",E10=""),1,MAX(1,DATEVALUE(E10)-DATEVALUE(D10))) -> 2 | G10: 43992 | H10: 48602 | L10: 21 | N10: =IF(G10="","",G10/F10) -> 21996 | O10: =IF(COUNT(H10:K10)=0,"",MIN(H10:K10)/F10) -> 24301 | P10: =IF(L10="","",L10*95/F10) -> 997.5 | Q10: =IF(OR(N10="",O10=""),"",(IF(AND(N10>7500,O10>7500),O10/(1+IF(O10<=1000,0,IF(O10<=7500,0.05,0.18)))-IF(AND(N10>7500,O10>7500),N10/1.18,N10),(O10-IF(AND(N10>7500,O10>7500),N10/1.18,N10))/(1+IF(O10<=1000,0,IF(O10<=7500,0.05,0.18)))))/(IF(AND(N10>7500,O10>7500),N10/1.18,N10))) -> 0.10479178 | R10: =IF(OR(N10="",O10=""),"",((O10-N10)/1.18)/N10) -> 0.088806593 | S10: =IF(OR(P10="",O10=""),"",(P10-O10)/O10) -> -0.95895231 | T10: =IF(AND(D10="",G10<>""),"no dates - assumed 1 night",IF(Q10="","",IF(Q10>1.5,"check: markup >150%",IF(Q10<0,"below cost",""))))
A11: Lonavala/Mahabaleshwar | B11: - Athiva Resort & Spa Khandala (Formerly Dukes Retreat) | C11: ~30d · mid-Aug | D11: 2026-08-28 | E11: 2026-08-30 | F11: =IF(OR(D11="",E11=""),1,MAX(1,DATEVALUE(E11)-DATEVALUE(D11))) -> 2 | G11: 36658 | H11: 42007 | N11: =IF(G11="","",G11/F11) -> 18329 | O11: =IF(COUNT(H11:K11)=0,"",MIN(H11:K11)/F11) -> 21003.5 | P11: =IF(L11="","",L11*95/F11) | Q11: =IF(OR(N11="",O11=""),"",(IF(AND(N11>7500,O11>7500),O11/(1+IF(O11<=1000,0,IF(O11<=7500,0.05,0.18)))-IF(AND(N11>7500,O11>7500),N11/1.18,N11),(O11-IF(AND(N11>7500,O11>7500),N11/1.18,N11))/(1+IF(O11<=1000,0,IF(O11<=7500,0.05,0.18)))))/(IF(AND(N11>7500,O11>7500),N11/1.18,N11))) -> 0.14591631 | R11: =IF(OR(N11="",O11=""),"",((O11-N11)/1.18)/N11) -> 0.12365789 | S11: =IF(OR(P11="",O11=""),"",(P11-O11)/O11) | T11: =IF(AND(D11="",G11<>""),"no dates - assumed 1 night",IF(Q11="","",IF(Q11>1.5,"check: markup >150%",IF(Q11<0,"below cost",""))))
A12: Lonavala/Mahabaleshwar | B12: - Athiva Resort & Spa Khandala (Formerly Dukes Retreat) | C12: mid-Oct · Diwali | D12: 2026-09-05 | E12: 2026-09-06 | F12: =IF(OR(D12="",E12=""),1,MAX(1,DATEVALUE(E12)-DATEVALUE(D12))) -> 1 | G12: 17218 | H12: 19905 | N12: =IF(G12="","",G12/F12) -> 17218 | O12: =IF(COUNT(H12:K12)=0,"",MIN(H12:K12)/F12) -> 19905 | P12: =IF(L12="","",L12*95/F12) | Q12: =IF(OR(N12="",O12=""),"",(IF(AND(N12>7500,O12>7500),O12/(1+IF(O12<=1000,0,IF(O12<=7500,0.05,0.18)))-IF(AND(N12>7500,O12>7500),N12/1.18,N12),(O12-IF(AND(N12>7500,O12>7500),N12/1.18,N12))/(1+IF(O12<=1000,0,IF(O12<=7500,0.05,0.18)))))/(IF(AND(N12>7500,O12>7500),N12/1.18,N12))) -> 0.15605761 | R12: =IF(OR(N12="",O12=""),"",((O12-N12)/1.18)/N12) -> 0.13225222 | S12: =IF(OR(P12="",O12=""),"",(P12-O12)/O12) | T12: =IF(AND(D12="",G12<>""),"no dates - assumed 1 night",IF(Q12="","",IF(Q12>1.5,"check: markup >150%",IF(Q12<0,"below cost",""))))
A13: Lonavala/Mahabaleshwar | B13: - Athiva Resort & Spa Khandala (Formerly Dukes Retreat) | C13: 27–30 Dec | D13: 2026-09-12 | E13: 2026-09-13 | F13: =IF(OR(D13="",E13=""),1,MAX(1,DATEVALUE(E13)-DATEVALUE(D13))) -> 1 | G13: 17218 | H13: 19905 | N13: =IF(G13="","",G13/F13) -> 17218 | O13: =IF(COUNT(H13:K13)=0,"",MIN(H13:K13)/F13) -> 19905 | P13: =IF(L13="","",L13*95/F13) | Q13: =IF(OR(N13="",O13=""),"",(IF(AND(N13>7500,O13>7500),O13/(1+IF(O13<=1000,0,IF(O13<=7500,0.05,0.18)))-IF(AND(N13>7500,O13>7500),N13/1.18,N13),(O13-IF(AND(N13>7500,O13>7500),N13/1.18,N13))/(1+IF(O13<=1000,0,IF(O13<=7500,0.05,0.18)))))/(IF(AND(N13>7500,O13>7500),N13/1.18,N13))) -> 0.15605761 | R13: =IF(OR(N13="",O13=""),"",((O13-N13)/1.18)/N13) -> 0.13225222 | S13: =IF(OR(P13="",O13=""),"",(P13-O13)/O13) | T13: =IF(AND(D13="",G13<>""),"no dates - assumed 1 night",IF(Q13="","",IF(Q13>1.5,"check: markup >150%",IF(Q13<0,"below cost",""))))
A14: Lonavala/Mahabaleshwar | B14: - Athiva Resort & Spa Khandala (Formerly Dukes Retreat) | C14: mid-Feb | D14: 2026-08-21 | E14: 2026-08-23 | F14: =IF(OR(D14="",E14=""),1,MAX(1,DATEVALUE(E14)-DATEVALUE(D14))) -> 2 | G14: 49433 | H14: 54648 | N14: =IF(G14="","",G14/F14) -> 24716.5 | O14: =IF(COUNT(H14:K14)=0,"",MIN(H14:K14)/F14) -> 27324 | P14: =IF(L14="","",L14*95/F14) | Q14: =IF(OR(N14="",O14=""),"",(IF(AND(N14>7500,O14>7500),O14/(1+IF(O14<=1000,0,IF(O14<=7500,0.05,0.18)))-IF(AND(N14>7500,O14>7500),N14/1.18,N14),(O14-IF(AND(N14>7500,O14>7500),N14/1.18,N14))/(1+IF(O14<=1000,0,IF(O14<=7500,0.05,0.18)))))/(IF(AND(N14>7500,O14>7500),N14/1.18,N14))) -> 0.10549633 | R14: =IF(OR(N14="",O14=""),"",((O14-N14)/1.18)/N14) -> 0.089403668 | S14: =IF(OR(P14="",O14=""),"",(P14-O14)/O14) | T14: =IF(AND(D14="",G14<>""),"no dates - assumed 1 night",IF(Q14="","",IF(Q14>1.5,"check: markup >150%",IF(Q14<0,"below cost",""))))
A15: Lonavala/Mahabaleshwar | B15: - Blue Country Resort, Panchgani | C15: ~7d · mid-Jul | D15: 2026-08-21 | E15: 2026-08-23 | F15: =IF(OR(D15="",E15=""),1,MAX(1,DATEVALUE(E15)-DATEVALUE(D15))) -> 2 | G15: 13574 | H15: 15691 | N15: =IF(G15="","",G15/F15) -> 6787 | O15: =IF(COUNT(H15:K15)=0,"",MIN(H15:K15)/F15) -> 7845.5 | P15: =IF(L15="","",L15*95/F15) | Q15: =IF(OR(N15="",O15=""),"",(IF(AND(N15>7500,O15>7500),O15/(1+IF(O15<=1000,0,IF(O15<=7500,0.05,0.18)))-IF(AND(N15>7500,O15>7500),N15/1.18,N15),(O15-IF(AND(N15>7500,O15>7500),N15/1.18,N15))/(1+IF(O15<=1000,0,IF(O15<=7500,0.05,0.18)))))/(IF(AND(N15>7500,O15>7500),N15/1.18,N15))) -> 0.13216943 | R15: =IF(OR(N15="",O15=""),"",((O15-N15)/1.18)/N15) -> 0.13216943 | S15: =IF(OR(P15="",O15=""),"",(P15-O15)/O15) | T15: =IF(AND(D15="",G15<>""),"no dates - assumed 1 night",IF(Q15="","",IF(Q15>1.5,"check: markup >150%",IF(Q15<0,"below cost",""))))
A16: Lonavala/Mahabaleshwar | B16: - Blue Country Resort, Panchgani | C16: ~30d · mid-Aug | D16: 2026-08-27 | E16: 2026-08-30 | F16: =IF(OR(D16="",E16=""),1,MAX(1,DATEVALUE(E16)-DATEVALUE(D16))) -> 3 | G16: 19646 | H16: 22684 | N16: =IF(G16="","",G16/F16) -> 6548.6667 | O16: =IF(COUNT(H16:K16)=0,"",MIN(H16:K16)/F16) -> 7561.3333 | P16: =IF(L16="","",L16*95/F16) | Q16: =IF(OR(N16="",O16=""),"",(IF(AND(N16>7500,O16>7500),O16/(1+IF(O16<=1000,0,IF(O16<=7500,0.05,0.18)))-IF(AND(N16>7500,O16>7500),N16/1.18,N16),(O16-IF(AND(N16>7500,O16>7500),N16/1.18,N16))/(1+IF(O16<=1000,0,IF(O16<=7500,0.05,0.18)))))/(IF(AND(N16>7500,O16>7500),N16/1.18,N16))) -> 0.13104837 | R16: =IF(OR(N16="",O16=""),"",((O16-N16)/1.18)/N16) -> 0.13104837 | S16: =IF(OR(P16="",O16=""),"",(P16-O16)/O16) | T16: =IF(AND(D16="",G16<>""),"no dates - assumed 1 night",IF(Q16="","",IF(Q16>1.5,"check: markup >150%",IF(Q16<0,"below cost",""))))
A17: Lonavala/Mahabaleshwar | B17: - Blue Country Resort, Panchgani | C17: 27–30 Dec | D17: 2026-09-11 | E17: 2026-09-13 | F17: =IF(OR(D17="",E17=""),1,MAX(1,DATEVALUE(E17)-DATEVALUE(D17))) -> 2 | G17: 13574 | H17: 14901 | N17: =IF(G17="","",G17/F17) -> 6787 | O17: =IF(COUNT(H17:K17)=0,"",MIN(H17:K17)/F17) -> 7450.5 | P17: =IF(L17="","",L17*95/F17) | Q17: =IF(OR(N17="",O17=""),"",(IF(AND(N17>7500,O17>7500),O17/(1+IF(O17<=1000,0,IF(O17<=7500,0.05,0.18)))-IF(AND(N17>7500,O17>7500),N17/1.18,N17),(O17-IF(AND(N17>7500,O17>7500),N17/1.18,N17))/(1+IF(O17<=1000,0,IF(O17<=7500,0.05,0.18)))))/(IF(AND(N17>7500,O17>7500),N17/1.18,N17))) -> 0.093105166 | R17: =IF(OR(N17="",O17=""),"",((O17-N17)/1.18)/N17) -> 0.082847817 | S17: =IF(OR(P17="",O17=""),"",(P17-O17)/O17) | T17: =IF(AND(D17="",G17<>""),"no dates - assumed 1 night",IF(Q17="","",IF(Q17>1.5,"check: markup >150%",IF(Q17<0,"below cost",""))))
A18: Lonavala/Mahabaleshwar | B18: - Brightland Resort & Spa | C18: ~7d · mid-Jul | D18: 2026-08-21 | E18: 2026-08-23 | F18: =IF(OR(D18="",E18=""),1,MAX(1,DATEVALUE(E18)-DATEVALUE(D18))) -> 2 | G18: 36198 | H18: 35863 | N18: =IF(G18="","",G18/F18) -> 18099 | O18: =IF(COUNT(H18:K18)=0,"",MIN(H18:K18)/F18) -> 17931.5 | P18: =IF(L18="","",L18*95/F18) | Q18: =IF(OR(N18="",O18=""),"",(IF(AND(N18>7500,O18>7500),O18/(1+IF(O18<=1000,0,IF(O18<=7500,0.05,0.18)))-IF(AND(N18>7500,O18>7500),N18/1.18,N18),(O18-IF(AND(N18>7500,O18>7500),N18/1.18,N18))/(1+IF(O18<=1000,0,IF(O18<=7500,0.05,0.18)))))/(IF(AND(N18>7500,O18>7500),N18/1.18,N18))) -> -0.009254655 | R18: =IF(OR(N18="",O18=""),"",((O18-N18)/1.18)/N18) -> -0.0078429279 | S18: =IF(OR(P18="",O18=""),"",(P18-O18)/O18) | T18: =IF(AND(D18="",G18<>""),"no dates - assumed 1 night",IF(Q18="","",IF(Q18>1.5,"check: markup >150%",IF(Q18<0,"below cost","")))) -> below cost
A19: Lonavala/Mahabaleshwar | B19: - Brightland Resort & Spa | C19: ~30d · mid-Aug | D19: 2026-08-27 | E19: 2026-08-30 | F19: =IF(OR(D19="",E19=""),1,MAX(1,DATEVALUE(E19)-DATEVALUE(D19))) -> 3 | G19: 43440 | H19: 52120 | N19: =IF(G19="","",G19/F19) -> 14480 | O19: =IF(COUNT(H19:K19)=0,"",MIN(H19:K19)/F19) -> 17373.333 | P19: =IF(L19="","",L19*95/F19) | Q19: =IF(OR(N19="",O19=""),"",(IF(AND(N19>7500,O19>7500),O19/(1+IF(O19<=1000,0,IF(O19<=7500,0.05,0.18)))-IF(AND(N19>7500,O19>7500),N19/1.18,N19),(O19-IF(AND(N19>7500,O19>7500),N19/1.18,N19))/(1+IF(O19<=1000,0,IF(O19<=7500,0.05,0.18)))))/(IF(AND(N19>7500,O19>7500),N19/1.18,N19))) -> 0.19981584 | R19: =IF(OR(N19="",O19=""),"",((O19-N19)/1.18)/N19) -> 0.16933546 | S19: =IF(OR(P19="",O19=""),"",(P19-O19)/O19) | T19: =IF(AND(D19="",G19<>""),"no dates - assumed 1 night",IF(Q19="","",IF(Q19>1.5,"check: markup >150%",IF(Q19<0,"below cost",""))))
A20: Lonavala/Mahabaleshwar | B20: - Brightland Resort & Spa | C20: mid-Oct · Diwali | D20: 2026-09-04 | E20: 2026-09-06 | F20: =IF(OR(D20="",E20=""),1,MAX(1,DATEVALUE(E20)-DATEVALUE(D20))) -> 2 | G20: 27571 | H20: 32603 | N20: =IF(G20="","",G20/F20) -> 13785.5 | O20: =IF(COUNT(H20:K20)=0,"",MIN(H20:K20)/F20) -> 16301.5 | P20: =IF(L20="","",L20*95/F20) | Q20: =IF(OR(N20="",O20=""),"",(IF(AND(N20>7500,O20>7500),O20/(1+IF(O20<=1000,0,IF(O20<=7500,0.05,0.18)))-IF(AND(N20>7500,O20>7500),N20/1.18,N20),(O20-IF(AND(N20>7500,O20>7500),N20/1.18,N20))/(1+IF(O20<=1000,0,IF(O20<=7500,0.05,0.18)))))/(IF(AND(N20>7500,O20>7500),N20/1.18,N20))) -> 0.18251061 | R20: =IF(OR(N20="",O20=""),"",((O20-N20)/1.18)/N20) -> 0.15467001 | S20: =IF(OR(P20="",O20=""),"",(P20-O20)/O20) | T20: =IF(AND(D20="",G20<>""),"no dates - assumed 1 night",IF(Q20="","",IF(Q20>1.5,"check: markup >150%",IF(Q20<0,"below cost",""))))
A21: Lonavala/Mahabaleshwar | B21: - Brightland Resort & Spa | C21: 27–30 Dec | D21: 2026-09-11 | E21: 2026-09-13 | F21: =IF(OR(D21="",E21=""),1,MAX(1,DATEVALUE(E21)-DATEVALUE(D21))) -> 2 | G21: 27571 | H21: 33113 | N21: =IF(G21="","",G21/F21) -> 13785.5 | O21: =IF(COUNT(H21:K21)=0,"",MIN(H21:K21)/F21) -> 16556.5 | P21: =IF(L21="","",L21*95/F21) | Q21: =IF(OR(N21="",O21=""),"",(IF(AND(N21>7500,O21>7500),O21/(1+IF(O21<=1000,0,IF(O21<=7500,0.05,0.18)))-IF(AND(N21>7500,O21>7500),N21/1.18,N21),(O21-IF(AND(N21>7500,O21>7500),N21/1.18,N21))/(1+IF(O21<=1000,0,IF(O21<=7500,0.05,0.18)))))/(IF(AND(N21>7500,O21>7500),N21/1.18,N21))) -> 0.20100831 | R21: =IF(OR(N21="",O21=""),"",((O21-N21)/1.18)/N21) -> 0.17034602 | S21: =IF(OR(P21="",O21=""),"",(P21-O21)/O21) | T21: =IF(AND(D21="",G21<>""),"no dates - assumed 1 night",IF(Q21="","",IF(Q21>1.5,"check: markup >150%",IF(Q21<0,"below cost",""))))
A22: Lonavala/Mahabaleshwar | B22: - Brightland Resort & Spa | C22: mid-Feb | D22: 2026-09-24 | E22: 2026-09-27 | F22: =IF(OR(D22="",E22=""),1,MAX(1,DATEVALUE(E22)-DATEVALUE(D22))) -> 3 | G22: 41400 | H22: 48951 | N22: =IF(G22="","",G22/F22) -> 13800 | O22: =IF(COUNT(H22:K22)=0,"",MIN(H22:K22)/F22) -> 16317 | P22: =IF(L22="","",L22*95/F22) | Q22: =IF(OR(N22="",O22=""),"",(IF(AND(N22>7500,O22>7500),O22/(1+IF(O22<=1000,0,IF(O22<=7500,0.05,0.18)))-IF(AND(N22>7500,O22>7500),N22/1.18,N22),(O22-IF(AND(N22>7500,O22>7500),N22/1.18,N22))/(1+IF(O22<=1000,0,IF(O22<=7500,0.05,0.18)))))/(IF(AND(N22>7500,O22>7500),N22/1.18,N22))) -> 0.1823913 | R22: =IF(OR(N22="",O22=""),"",((O22-N22)/1.18)/N22) -> 0.1545689 | S22: =IF(OR(P22="",O22=""),"",(P22-O22)/O22) | T22: =IF(AND(D22="",G22<>""),"no dates - assumed 1 night",IF(Q22="","",IF(Q22>1.5,"check: markup >150%",IF(Q22<0,"below cost",""))))
... A32: Lonavala/Mahabaleshwar | B32: - Courtyard by Marriott Mahabaleshwar | C32: mid-Feb | D32: 2026-09-24 | E32: 2026-09-27 | F32: =IF(OR(D32="",E32=""),1,MAX(1,DATEVALUE(E32)-DATEVALUE(D32))) -> 3 | G32: 56466 | H32: 57808 | N32: =IF(G32="","",G32/F32) -> 18822 | O32: =IF(COUNT(H32:K32)=0,"",MIN(H32:K32)/F32) -> 19269.333 | P32: =IF(L32="","",L32*95/F32) | Q32: =IF(OR(N32="",O32=""),"",(IF(AND(N32>7500,O32>7500),O32/(1+IF(O32<=1000,0,IF(O32<=7500,0.05,0.18)))-IF(AND(N32>7500,O32>7500),N32/1.18,N32),(O32-IF(AND(N32>7500,O32>7500),N32/1.18,N32))/(1+IF(O32<=1000,0,IF(O32<=7500,0.05,0.18)))))/(IF(AND(N32>7500,O32>7500),N32/1.18,N32))) -> 0.023766514 | R32: =IF(OR(N32="",O32=""),"",((O32-N32)/1.18)/N32) -> 0.020141114 | S32: =IF(OR(P32="",O32=""),"",(P32-O32)/O32) | T32: =IF(AND(D32="",G32<>""),"no dates - assumed 1 night",IF(Q32="","",IF(Q32>1.5,"check: markup >150%",IF(Q32<0,"below cost",""))))
